<?xml version='1.0'?>

<robot name="myrobot" xmlns:xacro="http://www.ros.org/wiki/xacro">

  <xacro:property name="cameraSize" value="0.05"/>
  <xacro:property name="cameraMass" value="0.1"/>

  <xacro:include filename="$(find mybot_description)/urdf/mybot.gazebo" />
  <xacro:include filename="$(find mybot_description)/urdf/materials.xacro" />
  <xacro:include filename="$(find mybot_description)/urdf/macros.xacro" />


  <link name='chassis'>
    <inertial>
      <mass value="75.0"/>
      <origin xyz="0.0 0 0.0" rpy=" 0 0 0"/>
      <inertia
          ixx="0.3125" ixy="0" ixz="0"
          iyy="4.25" iyz="0"
          izz="4.0625"
      />
    </inertial>

    <collision name='collision'>
      <origin xyz="0 0 0" rpy=" 0 0 0"/>
      <geometry>
        <box size=".8 .2 .1"/>
      </geometry>
    </collision>

    <visual name='chassis_visual'>
      <origin xyz="0 0 0" rpy=" 0 0 0"/>
      <geometry>
        <box size=".8 .2 .1"/>
      </geometry>
    </visual>


    <collision name='support1_collision'>
      <origin xyz="-0.375 0 -0.25" rpy=" 0 0 0"/>
      <geometry>
        <box size="0.05 0.2 0.4" />
      </geometry>
    </collision>

    <visual name='chassis_visual'>
      <origin xyz="-0.375 0 -0.25" rpy=" 0 0 0"/>
      <geometry>
        <box size="0.05 0.2 0.4" />
      </geometry>
    </visual>

    <collision name='support2_collision'>
      <origin xyz="0.375 0 -0.25" rpy=" 0 0 0"/>
      <geometry>
        <box size="0.05 0.2 0.4" />
      </geometry>
    </collision>

    <visual name='chassis_visual'>
      <origin xyz="0.375 0 -0.25" rpy=" 0 0 0"/>
      <geometry>
        <box size="0.05 0.2 0.4" />
      </geometry>
    </visual>


    

  </link>


  <link name="left_wheel">
    <!--origin xyz="0.1 0.13 0.1" rpy="0 1.5707 1.5707"/-->
    <collision name="collision">
      <origin xyz="0 0 0" rpy="0 1.5707 1.5707"/>
      <geometry>
        <cylinder radius="0.1" length="0.05"/>
      </geometry>
      <surface>
        <friction>
          <ode>
            <mu>200.0</mu>
            <mu2>200</mu2>
          </ode>
        </friction>
      </surface>
    </collision>
    <visual name="left_wheel_visual">
      <origin xyz="0 0 0" rpy="0 1.5707 1.5707"/>
      <geometry>
        <cylinder radius="0.1" length="0.05"/>
      </geometry>
    </visual>
    <inertial>
      <origin xyz="0 0 0" rpy="0 1.5707 1.5707"/>
      <mass value="0.5"/>
      <inertia
        ixx=".00135" ixy="0.0" ixz="0.0"
        iyy=".00135" iyz="0.0"
        izz=".0025"/>
    </inertial>
  </link>

<link name="left_wheel_rear">
    <!--origin xyz="0.1 0.13 0.1" rpy="0 1.5707 1.5707"/-->
    <collision name="collision">
      <origin xyz="0 0 0" rpy="0 1.5707 1.5707"/>
      <geometry>
        <cylinder radius="0.1" length="0.05"/>
      </geometry>
      <surface>
        <friction>
          <ode>
            <mu>200.0</mu>
            <mu2>200</mu2>
          </ode>
        </friction>
      </surface>
    </collision>
    <visual name="left_wheel_rear_visual">
      <origin xyz="0 0 0" rpy="0 1.5707 1.5707"/>
      <geometry>
        <cylinder radius="0.1" length="0.05"/>
      </geometry>
    </visual>
    <inertial>
      <origin xyz="0 0 0" rpy="0 1.5707 1.5707"/>
      <mass value="0.5"/>
      <inertia
        ixx=".00135" ixy="0.0" ixz="0.0"
        iyy=".00135" iyz="0.0"
        izz=".0025"/>
    </inertial>
  </link>

  <link name="right_wheel">
    <!--origin xyz="0.1 -0.13 0.1" rpy="0 1.5707 1.5707"/-->
    <collision name="collision">
      <origin xyz="0 0 0" rpy="0 -1.5707 -1.5707"/>
      <geometry>
        <cylinder radius="0.01" length="0.05"/>
      </geometry>
      <surface>
        <friction>
          <ode>
            <mu>200.0</mu>
            <mu2>200</mu2>
          </ode>
        </friction>
      </surface>
    </collision>
    <visual name="right_wheel_visual">
      <origin xyz="0 0 0" rpy="0 -1.5707 -1.5707"/>
      <geometry>
        <cylinder radius="0.01" length="0.05"/>
      </geometry>
    </visual>
    <inertial>
      <origin xyz="0 0 0" rpy="0 1.5707 1.5707"/>
      <mass value="0.5"/>
      <inertia
        ixx=".00135" ixy="0.0" ixz="0.0"
        iyy=".00135" iyz="0.0"
        izz=".0025"/>
    </inertial>
  </link>

  <link name="right_wheel_rear">
    <!--origin xyz="0.1 -0.13 0.1" rpy="0 1.5707 1.5707"/-->
    <collision name="collision">
      <origin xyz="0 0 0" rpy="0 -1.5707 -1.5707"/>
      <geometry>
        <cylinder radius="0.1" length="0.05"/>
      </geometry>
      <surface>
        <friction>
          <ode>
            <mu>200.0</mu>
            <mu2>200</mu2>
          </ode>
        </friction>
      </surface>
    </collision>
    <visual name="right_wheel_rear_visual">
      <origin xyz="0 0 0" rpy="0 -1.5707 -1.5707"/>
      <geometry>
        <cylinder radius="0.1" length="0.05"/>
      </geometry>
    </visual>
    <inertial>
      <origin xyz="0 0 0" rpy="0 1.5707 1.5707"/>
      <mass value="0.5"/>
      <inertia
        ixx=".00135" ixy="0.0" ixz="0.0"
        iyy=".00135" iyz="0.0"
        izz=".0025"/>
    </inertial>
  </link>

  <link name="imu_link">
    <!--origin xyz="0.1 -0.13 0.1" rpy="0 1.5707 1.5707"/-->
    <collision name="collision">
      <origin xyz="0 0 0" rpy="0 1.5707 1.5707"/>
      <geometry>
        <box size="0.01 0.01 0.01"/>
      </geometry>
    </collision>
    <visual name="imu_link_visual">
      <origin xyz="0 0 0" rpy="0 1.5707 1.5707"/>
      <geometry>
        <box size="0.01 0.01 0.01"/>
      </geometry>
    </visual>
    <inertial>
      <origin xyz="0 0 0" rpy="0 1.5707 1.5707"/>
      <mass value="0.0001"/>
      <inertia
        ixx=".000001" ixy="0.0" ixz="0.0"
        iyy=".000001" iyz="0.0"
        izz=".000001"/>
    </inertial>
  </link>

  <joint type="fixed" name="imu_hinge">
    <origin xyz="0 0 0.055" rpy="0 0 0"/>
    <!--origin xyz="0.1 -0.13 0" rpy="0 1.5707 1.5707"/-->
    <child link="imu_link"/>
    <parent link="chassis"/>
    <axis xyz="0 1 0" rpy="0 0 0"/>
    <limit effort="10000" velocity="1000"/>
    <joint_properties damping="1.0" friction="1.0"/>
  </joint>


  <joint type="continuous" name="left_wheel_hinge">
    <origin xyz="0.375 0.0 -0.4" rpy="0 0 0"/>
    <!--origin xyz="0.1 0.13 0" rpy="0 1.5707 1.5707"/-->
    <child link="left_wheel"/>
    <parent link="chassis"/>
    <axis xyz="0 1 0" rpy="0 0 0"/>
    <limit effort="100" velocity="100"/>
    <joint_properties damping="10.0" friction="10.0"/>
  </joint>

  <joint type="continuous" name="right_wheel_hinge">
    <origin xyz="0.375 -0.13 -0.4" rpy="0 0 0"/>
    <!--origin xyz="0.1 -0.13 0" rpy="0 1.5707 1.5707"/-->
    <child link="right_wheel"/>
    <parent link="chassis"/>
    <axis xyz="0 1 0" rpy="0 0 0"/>
    <limit effort="100" velocity="100"/>
    <joint_properties damping="10.0" friction="10.0"/>
  </joint>


  <joint type="continuous" name="left_wheel_rear_hinge">
    <origin xyz="-0.375 0.13 -0.4" rpy="0 0 0"/>
    <!--origin xyz="0.1 0.13 0" rpy="0 1.5707 1.5707"/-->
    <child link="left_wheel_rear"/>
    <parent link="chassis"/>
    <axis xyz="0 1 0" rpy="0 0 0"/>
    <limit effort="100" velocity="100"/>
    <joint_properties damping="10.0" friction="0.0"/>
  </joint>

  <joint type="continuous" name="right_wheel_rear_hinge">
    <origin xyz="-0.375 -0.13 -0.4" rpy="0 0 0"/>
    <!--origin xyz="0.1 -0.13 0" rpy="0 1.5707 1.5707"/-->
    <child link="right_wheel_rear"/>
    <parent link="chassis"/>
    <axis xyz="0 1 0" rpy="0 0 0"/>
    <limit effort="100" velocity="100"/>
    <joint_properties damping="10.0" friction="0.0"/>
  </joint>

  <transmission name="tran_LF">
    <type>transmission_interface/SimpleTransmission</type>
    <joint name="left_wheel_hinge">
      <hardwareInterface>hardware_interface/EffortJointInterface</hardwareInterface>
    </joint>
    <actuator name="motor_LF">
      <hardwareInterface>hardware_interface/EffortJointInterface</hardwareInterface>
      <mechanicalReduction>1</mechanicalReduction>
    </actuator>
  </transmission>

  <transmission name="tran_RF">
    <type>transmission_interface/SimpleTransmission</type>
    <joint name="right_wheel_hinge">
      <hardwareInterface>hardware_interface/EffortJointInterface</hardwareInterface>
    </joint>
    <actuator name="motor_RF">
      <hardwareInterface>hardware_interface/EffortJointInterface</hardwareInterface>
      <mechanicalReduction>1</mechanicalReduction>
    </actuator>
  </transmission>

  <transmission name="tran_LR">
    <type>transmission_interface/SimpleTransmission</type>
    <joint name="left_wheel_rear_hinge">
      <hardwareInterface>hardware_interface/EffortJointInterface</hardwareInterface>
    </joint>
    <actuator name="motor_LR">
      <hardwareInterface>hardware_interface/EffortJointInterface</hardwareInterface>
      <mechanicalReduction>1</mechanicalReduction>
    </actuator>
  </transmission>

  <transmission name="tran_RR">
    <type>transmission_interface/SimpleTransmission</type>
    <joint name="right_wheel_rear_hinge">
      <hardwareInterface>hardware_interface/EffortJointInterface</hardwareInterface>
    </joint>
    <actuator name="motor_RR">
      <hardwareInterface>hardware_interface/EffortJointInterface</hardwareInterface>
      <mechanicalReduction>1</mechanicalReduction>
    </actuator>
  </transmission>



</robot>

